{
 "cells": [
  {
   "cell_type": "code",
   "execution_count": 1,
   "id": "10f3da9c",
   "metadata": {},
   "outputs": [
    {
     "name": "stdout",
     "output_type": "stream",
     "text": [
      "Requirement already satisfied: keras in c:\\users\\smiry\\anaconda3\\lib\\site-packages (2.11.0)\n",
      "Note: you may need to restart the kernel to use updated packages.\n"
     ]
    }
   ],
   "source": [
    "pip install keras"
   ]
  },
  {
   "cell_type": "code",
   "execution_count": 2,
   "id": "b731fe68",
   "metadata": {},
   "outputs": [
    {
     "name": "stdout",
     "output_type": "stream",
     "text": [
      "Requirement already satisfied: tensorflow in c:\\users\\smiry\\anaconda3\\lib\\site-packages (2.11.0)\n",
      "Requirement already satisfied: tensorflow-intel==2.11.0 in c:\\users\\smiry\\anaconda3\\lib\\site-packages (from tensorflow) (2.11.0)\n",
      "Requirement already satisfied: setuptools in c:\\users\\smiry\\anaconda3\\lib\\site-packages (from tensorflow-intel==2.11.0->tensorflow) (63.4.1)\n",
      "Requirement already satisfied: absl-py>=1.0.0 in c:\\users\\smiry\\anaconda3\\lib\\site-packages (from tensorflow-intel==2.11.0->tensorflow) (1.4.0)\n",
      "Requirement already satisfied: typing-extensions>=3.6.6 in c:\\users\\smiry\\anaconda3\\lib\\site-packages (from tensorflow-intel==2.11.0->tensorflow) (4.3.0)\n",
      "Requirement already satisfied: flatbuffers>=2.0 in c:\\users\\smiry\\anaconda3\\lib\\site-packages (from tensorflow-intel==2.11.0->tensorflow) (23.1.21)\n",
      "Requirement already satisfied: packaging in c:\\users\\smiry\\anaconda3\\lib\\site-packages (from tensorflow-intel==2.11.0->tensorflow) (21.3)\n",
      "Requirement already satisfied: h5py>=2.9.0 in c:\\users\\smiry\\anaconda3\\lib\\site-packages (from tensorflow-intel==2.11.0->tensorflow) (3.7.0)\n",
      "Requirement already satisfied: keras<2.12,>=2.11.0 in c:\\users\\smiry\\anaconda3\\lib\\site-packages (from tensorflow-intel==2.11.0->tensorflow) (2.11.0)\n",
      "Requirement already satisfied: tensorflow-io-gcs-filesystem>=0.23.1 in c:\\users\\smiry\\anaconda3\\lib\\site-packages (from tensorflow-intel==2.11.0->tensorflow) (0.30.0)\n",
      "Requirement already satisfied: libclang>=13.0.0 in c:\\users\\smiry\\anaconda3\\lib\\site-packages (from tensorflow-intel==2.11.0->tensorflow) (15.0.6.1)\n",
      "Requirement already satisfied: astunparse>=1.6.0 in c:\\users\\smiry\\anaconda3\\lib\\site-packages (from tensorflow-intel==2.11.0->tensorflow) (1.6.3)\n",
      "Requirement already satisfied: tensorflow-estimator<2.12,>=2.11.0 in c:\\users\\smiry\\anaconda3\\lib\\site-packages (from tensorflow-intel==2.11.0->tensorflow) (2.11.0)\n",
      "Requirement already satisfied: grpcio<2.0,>=1.24.3 in c:\\users\\smiry\\anaconda3\\lib\\site-packages (from tensorflow-intel==2.11.0->tensorflow) (1.51.1)\n",
      "Requirement already satisfied: google-pasta>=0.1.1 in c:\\users\\smiry\\anaconda3\\lib\\site-packages (from tensorflow-intel==2.11.0->tensorflow) (0.2.0)\n",
      "Requirement already satisfied: protobuf<3.20,>=3.9.2 in c:\\users\\smiry\\anaconda3\\lib\\site-packages (from tensorflow-intel==2.11.0->tensorflow) (3.19.6)\n",
      "Requirement already satisfied: numpy>=1.20 in c:\\users\\smiry\\anaconda3\\lib\\site-packages (from tensorflow-intel==2.11.0->tensorflow) (1.21.5)\n",
      "Requirement already satisfied: wrapt>=1.11.0 in c:\\users\\smiry\\anaconda3\\lib\\site-packages (from tensorflow-intel==2.11.0->tensorflow) (1.14.1)\n",
      "Requirement already satisfied: six>=1.12.0 in c:\\users\\smiry\\anaconda3\\lib\\site-packages (from tensorflow-intel==2.11.0->tensorflow) (1.16.0)\n",
      "Requirement already satisfied: gast<=0.4.0,>=0.2.1 in c:\\users\\smiry\\anaconda3\\lib\\site-packages (from tensorflow-intel==2.11.0->tensorflow) (0.4.0)\n",
      "Requirement already satisfied: tensorboard<2.12,>=2.11 in c:\\users\\smiry\\anaconda3\\lib\\site-packages (from tensorflow-intel==2.11.0->tensorflow) (2.11.2)\n",
      "Requirement already satisfied: termcolor>=1.1.0 in c:\\users\\smiry\\anaconda3\\lib\\site-packages (from tensorflow-intel==2.11.0->tensorflow) (2.2.0)\n",
      "Requirement already satisfied: opt-einsum>=2.3.2 in c:\\users\\smiry\\anaconda3\\lib\\site-packages (from tensorflow-intel==2.11.0->tensorflow) (3.3.0)\n",
      "Requirement already satisfied: wheel<1.0,>=0.23.0 in c:\\users\\smiry\\anaconda3\\lib\\site-packages (from astunparse>=1.6.0->tensorflow-intel==2.11.0->tensorflow) (0.37.1)\n",
      "Requirement already satisfied: requests<3,>=2.21.0 in c:\\users\\smiry\\anaconda3\\lib\\site-packages (from tensorboard<2.12,>=2.11->tensorflow-intel==2.11.0->tensorflow) (2.28.1)\n",
      "Requirement already satisfied: google-auth<3,>=1.6.3 in c:\\users\\smiry\\anaconda3\\lib\\site-packages (from tensorboard<2.12,>=2.11->tensorflow-intel==2.11.0->tensorflow) (2.16.1)\n",
      "Requirement already satisfied: werkzeug>=1.0.1 in c:\\users\\smiry\\anaconda3\\lib\\site-packages (from tensorboard<2.12,>=2.11->tensorflow-intel==2.11.0->tensorflow) (2.0.3)\n",
      "Requirement already satisfied: tensorboard-plugin-wit>=1.6.0 in c:\\users\\smiry\\anaconda3\\lib\\site-packages (from tensorboard<2.12,>=2.11->tensorflow-intel==2.11.0->tensorflow) (1.8.1)\n",
      "Requirement already satisfied: google-auth-oauthlib<0.5,>=0.4.1 in c:\\users\\smiry\\anaconda3\\lib\\site-packages (from tensorboard<2.12,>=2.11->tensorflow-intel==2.11.0->tensorflow) (0.4.6)\n",
      "Requirement already satisfied: tensorboard-data-server<0.7.0,>=0.6.0 in c:\\users\\smiry\\anaconda3\\lib\\site-packages (from tensorboard<2.12,>=2.11->tensorflow-intel==2.11.0->tensorflow) (0.6.1)\n",
      "Requirement already satisfied: markdown>=2.6.8 in c:\\users\\smiry\\anaconda3\\lib\\site-packages (from tensorboard<2.12,>=2.11->tensorflow-intel==2.11.0->tensorflow) (3.3.4)\n",
      "Requirement already satisfied: pyparsing!=3.0.5,>=2.0.2 in c:\\users\\smiry\\anaconda3\\lib\\site-packages (from packaging->tensorflow-intel==2.11.0->tensorflow) (3.0.9)\n",
      "Requirement already satisfied: rsa<5,>=3.1.4 in c:\\users\\smiry\\anaconda3\\lib\\site-packages (from google-auth<3,>=1.6.3->tensorboard<2.12,>=2.11->tensorflow-intel==2.11.0->tensorflow) (4.9)\n",
      "Requirement already satisfied: cachetools<6.0,>=2.0.0 in c:\\users\\smiry\\anaconda3\\lib\\site-packages (from google-auth<3,>=1.6.3->tensorboard<2.12,>=2.11->tensorflow-intel==2.11.0->tensorflow) (5.3.0)\n",
      "Requirement already satisfied: pyasn1-modules>=0.2.1 in c:\\users\\smiry\\anaconda3\\lib\\site-packages (from google-auth<3,>=1.6.3->tensorboard<2.12,>=2.11->tensorflow-intel==2.11.0->tensorflow) (0.2.8)\n",
      "Requirement already satisfied: requests-oauthlib>=0.7.0 in c:\\users\\smiry\\anaconda3\\lib\\site-packages (from google-auth-oauthlib<0.5,>=0.4.1->tensorboard<2.12,>=2.11->tensorflow-intel==2.11.0->tensorflow) (1.3.1)\n",
      "Requirement already satisfied: urllib3<1.27,>=1.21.1 in c:\\users\\smiry\\anaconda3\\lib\\site-packages (from requests<3,>=2.21.0->tensorboard<2.12,>=2.11->tensorflow-intel==2.11.0->tensorflow) (1.26.11)\n",
      "Requirement already satisfied: idna<4,>=2.5 in c:\\users\\smiry\\anaconda3\\lib\\site-packages (from requests<3,>=2.21.0->tensorboard<2.12,>=2.11->tensorflow-intel==2.11.0->tensorflow) (3.3)\n",
      "Requirement already satisfied: certifi>=2017.4.17 in c:\\users\\smiry\\anaconda3\\lib\\site-packages (from requests<3,>=2.21.0->tensorboard<2.12,>=2.11->tensorflow-intel==2.11.0->tensorflow) (2022.9.14)\n",
      "Requirement already satisfied: charset-normalizer<3,>=2 in c:\\users\\smiry\\anaconda3\\lib\\site-packages (from requests<3,>=2.21.0->tensorboard<2.12,>=2.11->tensorflow-intel==2.11.0->tensorflow) (2.0.4)\n",
      "Requirement already satisfied: pyasn1<0.5.0,>=0.4.6 in c:\\users\\smiry\\anaconda3\\lib\\site-packages (from pyasn1-modules>=0.2.1->google-auth<3,>=1.6.3->tensorboard<2.12,>=2.11->tensorflow-intel==2.11.0->tensorflow) (0.4.8)\n",
      "Requirement already satisfied: oauthlib>=3.0.0 in c:\\users\\smiry\\anaconda3\\lib\\site-packages (from requests-oauthlib>=0.7.0->google-auth-oauthlib<0.5,>=0.4.1->tensorboard<2.12,>=2.11->tensorflow-intel==2.11.0->tensorflow) (3.2.2)\n",
      "Note: you may need to restart the kernel to use updated packages.\n"
     ]
    }
   ],
   "source": [
    "pip install tensorflow --user"
   ]
  },
  {
   "cell_type": "code",
   "execution_count": 3,
   "id": "859f7173",
   "metadata": {},
   "outputs": [],
   "source": [
    "import pandas as pd\n",
    "import matplotlib.pyplot as plt\n",
    "\n",
    "from keras.models import Sequential\n",
    "from keras.layers import Conv2D\n",
    "from keras.layers import MaxPooling2D\n",
    "from keras.layers import Flatten\n",
    "from keras.layers import Dense\n",
    "from keras.layers import Dropout"
   ]
  },
  {
   "cell_type": "code",
   "execution_count": 4,
   "id": "6895fea1",
   "metadata": {},
   "outputs": [],
   "source": [
    "from keras.preprocessing.image import ImageDataGenerator\n",
    "\n",
    "train_datagen = ImageDataGenerator(rescale = 1./225,\n",
    "                                  shear_range = 0.2,\n",
    "                                  zoom_range = 0.2,\n",
    "                                  horizontal_flip = True)\n",
    "\n",
    "test_datagen = ImageDataGenerator(rescale = 1./255)"
   ]
  },
  {
   "cell_type": "code",
   "execution_count": 5,
   "id": "de14b3f5",
   "metadata": {},
   "outputs": [
    {
     "name": "stdout",
     "output_type": "stream",
     "text": [
      "Found 3110 images belonging to 24 classes.\n"
     ]
    }
   ],
   "source": [
    "test_set = test_datagen.flow_from_directory('C:/Users/smiry/fruits-360-original-size/Test',\n",
    "                                           target_size = (100, 100),\n",
    "                                           batch_size = 32,\n",
    "                                           class_mode ='categorical', shuffle = False)"
   ]
  },
  {
   "cell_type": "code",
   "execution_count": 6,
   "id": "180f47de",
   "metadata": {},
   "outputs": [
    {
     "name": "stdout",
     "output_type": "stream",
     "text": [
      "Found 6231 images belonging to 24 classes.\n"
     ]
    }
   ],
   "source": [
    "training_set = train_datagen.flow_from_directory('C:/Users/smiry/fruits-360-original-size/Training',\n",
    "                                           target_size = (100, 100),\n",
    "                                           batch_size = 32,\n",
    "                                           class_mode ='categorical', shuffle = True)"
   ]
  },
  {
   "cell_type": "code",
   "execution_count": 7,
   "id": "55bbc254",
   "metadata": {},
   "outputs": [],
   "source": [
    "# Initialising the CNN\n",
    "Model = Sequential()\n",
    "\n",
    "# Step 1 - Convolution\n",
    "Model.add(Conv2D(16, (2, 2), input_shape = (100, 100, 3), activation = 'relu'))\n",
    "# Step 2 - Pooling\n",
    "Model.add(MaxPooling2D(pool_size = (2, 2)))\n",
    "\n",
    "# Adding a second convolutional layer\n",
    "Model.add(Conv2D(32, (2, 2), activation = 'relu'))\n",
    "\n",
    "Model.add(MaxPooling2D(pool_size = (2, 2)))\n",
    "\n",
    "Model.add(Conv2D(64, (2, 2), activation = 'relu'))\n",
    "Model.add(Conv2D(64, (2, 2), activation = 'relu'))\n",
    "\n",
    "Model.add(MaxPooling2D(pool_size = (2, 2)))\n",
    "\n",
    "Model.add(Dropout(0.3))\n",
    "\n",
    "# Step 3 - Flattening\n",
    "Model.add(Flatten())\n",
    "\n",
    "# Step 4 - Full connection\n",
    "Model.add(Dense(units = 150, activation = 'relu'))\n",
    "\n",
    "Model.add(Dropout(0.4))\n",
    "\n",
    "Model.add(Dense(units = 131, activation = 'softmax'))"
   ]
  },
  {
   "cell_type": "code",
   "execution_count": 8,
   "id": "0b6ab750",
   "metadata": {},
   "outputs": [],
   "source": [
    "Model.compile(optimizer = 'rmsprop', loss = 'categorical_crossentropy', metrics = ['accuracy'])"
   ]
  },
  {
   "cell_type": "code",
   "execution_count": 9,
   "id": "4e436170",
   "metadata": {},
   "outputs": [
    {
     "name": "stdout",
     "output_type": "stream",
     "text": [
      "Epoch 1/30\n"
     ]
    },
    {
     "name": "stderr",
     "output_type": "stream",
     "text": [
      "C:\\Users\\smiry\\AppData\\Local\\Temp\\ipykernel_5000\\233132255.py:1: UserWarning: `Model.fit_generator` is deprecated and will be removed in a future version. Please use `Model.fit`, which supports generators.\n",
      "  cnn = Model.fit_generator(generator = training_set,\n"
     ]
    },
    {
     "ename": "InvalidArgumentError",
     "evalue": "Graph execution error:\n\nDetected at node 'categorical_crossentropy/softmax_cross_entropy_with_logits' defined at (most recent call last):\n    File \"C:\\Users\\smiry\\Anaconda3\\lib\\runpy.py\", line 197, in _run_module_as_main\n      return _run_code(code, main_globals, None,\n    File \"C:\\Users\\smiry\\Anaconda3\\lib\\runpy.py\", line 87, in _run_code\n      exec(code, run_globals)\n    File \"C:\\Users\\smiry\\Anaconda3\\lib\\site-packages\\ipykernel_launcher.py\", line 17, in <module>\n      app.launch_new_instance()\n    File \"C:\\Users\\smiry\\Anaconda3\\lib\\site-packages\\traitlets\\config\\application.py\", line 846, in launch_instance\n      app.start()\n    File \"C:\\Users\\smiry\\Anaconda3\\lib\\site-packages\\ipykernel\\kernelapp.py\", line 712, in start\n      self.io_loop.start()\n    File \"C:\\Users\\smiry\\Anaconda3\\lib\\site-packages\\tornado\\platform\\asyncio.py\", line 199, in start\n      self.asyncio_loop.run_forever()\n    File \"C:\\Users\\smiry\\Anaconda3\\lib\\asyncio\\base_events.py\", line 601, in run_forever\n      self._run_once()\n    File \"C:\\Users\\smiry\\Anaconda3\\lib\\asyncio\\base_events.py\", line 1905, in _run_once\n      handle._run()\n    File \"C:\\Users\\smiry\\Anaconda3\\lib\\asyncio\\events.py\", line 80, in _run\n      self._context.run(self._callback, *self._args)\n    File \"C:\\Users\\smiry\\Anaconda3\\lib\\site-packages\\ipykernel\\kernelbase.py\", line 510, in dispatch_queue\n      await self.process_one()\n    File \"C:\\Users\\smiry\\Anaconda3\\lib\\site-packages\\ipykernel\\kernelbase.py\", line 499, in process_one\n      await dispatch(*args)\n    File \"C:\\Users\\smiry\\Anaconda3\\lib\\site-packages\\ipykernel\\kernelbase.py\", line 406, in dispatch_shell\n      await result\n    File \"C:\\Users\\smiry\\Anaconda3\\lib\\site-packages\\ipykernel\\kernelbase.py\", line 730, in execute_request\n      reply_content = await reply_content\n    File \"C:\\Users\\smiry\\Anaconda3\\lib\\site-packages\\ipykernel\\ipkernel.py\", line 390, in do_execute\n      res = shell.run_cell(code, store_history=store_history, silent=silent)\n    File \"C:\\Users\\smiry\\Anaconda3\\lib\\site-packages\\ipykernel\\zmqshell.py\", line 528, in run_cell\n      return super().run_cell(*args, **kwargs)\n    File \"C:\\Users\\smiry\\Anaconda3\\lib\\site-packages\\IPython\\core\\interactiveshell.py\", line 2914, in run_cell\n      result = self._run_cell(\n    File \"C:\\Users\\smiry\\Anaconda3\\lib\\site-packages\\IPython\\core\\interactiveshell.py\", line 2960, in _run_cell\n      return runner(coro)\n    File \"C:\\Users\\smiry\\Anaconda3\\lib\\site-packages\\IPython\\core\\async_helpers.py\", line 78, in _pseudo_sync_runner\n      coro.send(None)\n    File \"C:\\Users\\smiry\\Anaconda3\\lib\\site-packages\\IPython\\core\\interactiveshell.py\", line 3185, in run_cell_async\n      has_raised = await self.run_ast_nodes(code_ast.body, cell_name,\n    File \"C:\\Users\\smiry\\Anaconda3\\lib\\site-packages\\IPython\\core\\interactiveshell.py\", line 3377, in run_ast_nodes\n      if (await self.run_code(code, result,  async_=asy)):\n    File \"C:\\Users\\smiry\\Anaconda3\\lib\\site-packages\\IPython\\core\\interactiveshell.py\", line 3457, in run_code\n      exec(code_obj, self.user_global_ns, self.user_ns)\n    File \"C:\\Users\\smiry\\AppData\\Local\\Temp\\ipykernel_5000\\233132255.py\", line 1, in <module>\n      cnn = Model.fit_generator(generator = training_set,\n    File \"C:\\Users\\smiry\\Anaconda3\\lib\\site-packages\\keras\\engine\\training.py\", line 2604, in fit_generator\n      return self.fit(\n    File \"C:\\Users\\smiry\\Anaconda3\\lib\\site-packages\\keras\\utils\\traceback_utils.py\", line 65, in error_handler\n      return fn(*args, **kwargs)\n    File \"C:\\Users\\smiry\\Anaconda3\\lib\\site-packages\\keras\\engine\\training.py\", line 1650, in fit\n      tmp_logs = self.train_function(iterator)\n    File \"C:\\Users\\smiry\\Anaconda3\\lib\\site-packages\\keras\\engine\\training.py\", line 1249, in train_function\n      return step_function(self, iterator)\n    File \"C:\\Users\\smiry\\Anaconda3\\lib\\site-packages\\keras\\engine\\training.py\", line 1233, in step_function\n      outputs = model.distribute_strategy.run(run_step, args=(data,))\n    File \"C:\\Users\\smiry\\Anaconda3\\lib\\site-packages\\keras\\engine\\training.py\", line 1222, in run_step\n      outputs = model.train_step(data)\n    File \"C:\\Users\\smiry\\Anaconda3\\lib\\site-packages\\keras\\engine\\training.py\", line 1024, in train_step\n      loss = self.compute_loss(x, y, y_pred, sample_weight)\n    File \"C:\\Users\\smiry\\Anaconda3\\lib\\site-packages\\keras\\engine\\training.py\", line 1082, in compute_loss\n      return self.compiled_loss(\n    File \"C:\\Users\\smiry\\Anaconda3\\lib\\site-packages\\keras\\engine\\compile_utils.py\", line 265, in __call__\n      loss_value = loss_obj(y_t, y_p, sample_weight=sw)\n    File \"C:\\Users\\smiry\\Anaconda3\\lib\\site-packages\\keras\\losses.py\", line 152, in __call__\n      losses = call_fn(y_true, y_pred)\n    File \"C:\\Users\\smiry\\Anaconda3\\lib\\site-packages\\keras\\losses.py\", line 284, in call\n      return ag_fn(y_true, y_pred, **self._fn_kwargs)\n    File \"C:\\Users\\smiry\\Anaconda3\\lib\\site-packages\\keras\\losses.py\", line 2004, in categorical_crossentropy\n      return backend.categorical_crossentropy(\n    File \"C:\\Users\\smiry\\Anaconda3\\lib\\site-packages\\keras\\backend.py\", line 5538, in categorical_crossentropy\n      return tf.nn.softmax_cross_entropy_with_logits(\nNode: 'categorical_crossentropy/softmax_cross_entropy_with_logits'\nlogits and labels must be broadcastable: logits_size=[32,131] labels_size=[32,24]\n\t [[{{node categorical_crossentropy/softmax_cross_entropy_with_logits}}]] [Op:__inference_train_function_1307]",
     "output_type": "error",
     "traceback": [
      "\u001b[1;31m---------------------------------------------------------------------------\u001b[0m",
      "\u001b[1;31mInvalidArgumentError\u001b[0m                      Traceback (most recent call last)",
      "\u001b[1;32m~\\AppData\\Local\\Temp\\ipykernel_5000\\233132255.py\u001b[0m in \u001b[0;36m<module>\u001b[1;34m\u001b[0m\n\u001b[1;32m----> 1\u001b[1;33m cnn = Model.fit_generator(generator = training_set,\n\u001b[0m\u001b[0;32m      2\u001b[0m                          \u001b[0msteps_per_epoch\u001b[0m \u001b[1;33m=\u001b[0m \u001b[1;36m1000\u001b[0m\u001b[1;33m,\u001b[0m\u001b[1;33m\u001b[0m\u001b[1;33m\u001b[0m\u001b[0m\n\u001b[0;32m      3\u001b[0m                          \u001b[0mepochs\u001b[0m \u001b[1;33m=\u001b[0m \u001b[1;36m30\u001b[0m\u001b[1;33m,\u001b[0m\u001b[1;33m\u001b[0m\u001b[1;33m\u001b[0m\u001b[0m\n\u001b[0;32m      4\u001b[0m                          \u001b[0mvalidation_data\u001b[0m \u001b[1;33m=\u001b[0m \u001b[0mtest_set\u001b[0m\u001b[1;33m,\u001b[0m\u001b[1;33m\u001b[0m\u001b[1;33m\u001b[0m\u001b[0m\n\u001b[0;32m      5\u001b[0m                          validation_steps = 100)\n",
      "\u001b[1;32m~\\Anaconda3\\lib\\site-packages\\keras\\engine\\training.py\u001b[0m in \u001b[0;36mfit_generator\u001b[1;34m(self, generator, steps_per_epoch, epochs, verbose, callbacks, validation_data, validation_steps, validation_freq, class_weight, max_queue_size, workers, use_multiprocessing, shuffle, initial_epoch)\u001b[0m\n\u001b[0;32m   2602\u001b[0m             \u001b[0mstacklevel\u001b[0m\u001b[1;33m=\u001b[0m\u001b[1;36m2\u001b[0m\u001b[1;33m,\u001b[0m\u001b[1;33m\u001b[0m\u001b[1;33m\u001b[0m\u001b[0m\n\u001b[0;32m   2603\u001b[0m         )\n\u001b[1;32m-> 2604\u001b[1;33m         return self.fit(\n\u001b[0m\u001b[0;32m   2605\u001b[0m             \u001b[0mgenerator\u001b[0m\u001b[1;33m,\u001b[0m\u001b[1;33m\u001b[0m\u001b[1;33m\u001b[0m\u001b[0m\n\u001b[0;32m   2606\u001b[0m             \u001b[0msteps_per_epoch\u001b[0m\u001b[1;33m=\u001b[0m\u001b[0msteps_per_epoch\u001b[0m\u001b[1;33m,\u001b[0m\u001b[1;33m\u001b[0m\u001b[1;33m\u001b[0m\u001b[0m\n",
      "\u001b[1;32m~\\Anaconda3\\lib\\site-packages\\keras\\utils\\traceback_utils.py\u001b[0m in \u001b[0;36merror_handler\u001b[1;34m(*args, **kwargs)\u001b[0m\n\u001b[0;32m     68\u001b[0m             \u001b[1;31m# To get the full stack trace, call:\u001b[0m\u001b[1;33m\u001b[0m\u001b[1;33m\u001b[0m\u001b[0m\n\u001b[0;32m     69\u001b[0m             \u001b[1;31m# `tf.debugging.disable_traceback_filtering()`\u001b[0m\u001b[1;33m\u001b[0m\u001b[1;33m\u001b[0m\u001b[0m\n\u001b[1;32m---> 70\u001b[1;33m             \u001b[1;32mraise\u001b[0m \u001b[0me\u001b[0m\u001b[1;33m.\u001b[0m\u001b[0mwith_traceback\u001b[0m\u001b[1;33m(\u001b[0m\u001b[0mfiltered_tb\u001b[0m\u001b[1;33m)\u001b[0m \u001b[1;32mfrom\u001b[0m \u001b[1;32mNone\u001b[0m\u001b[1;33m\u001b[0m\u001b[1;33m\u001b[0m\u001b[0m\n\u001b[0m\u001b[0;32m     71\u001b[0m         \u001b[1;32mfinally\u001b[0m\u001b[1;33m:\u001b[0m\u001b[1;33m\u001b[0m\u001b[1;33m\u001b[0m\u001b[0m\n\u001b[0;32m     72\u001b[0m             \u001b[1;32mdel\u001b[0m \u001b[0mfiltered_tb\u001b[0m\u001b[1;33m\u001b[0m\u001b[1;33m\u001b[0m\u001b[0m\n",
      "\u001b[1;32m~\\Anaconda3\\lib\\site-packages\\tensorflow\\python\\eager\\execute.py\u001b[0m in \u001b[0;36mquick_execute\u001b[1;34m(op_name, num_outputs, inputs, attrs, ctx, name)\u001b[0m\n\u001b[0;32m     50\u001b[0m   \u001b[1;32mtry\u001b[0m\u001b[1;33m:\u001b[0m\u001b[1;33m\u001b[0m\u001b[1;33m\u001b[0m\u001b[0m\n\u001b[0;32m     51\u001b[0m     \u001b[0mctx\u001b[0m\u001b[1;33m.\u001b[0m\u001b[0mensure_initialized\u001b[0m\u001b[1;33m(\u001b[0m\u001b[1;33m)\u001b[0m\u001b[1;33m\u001b[0m\u001b[1;33m\u001b[0m\u001b[0m\n\u001b[1;32m---> 52\u001b[1;33m     tensors = pywrap_tfe.TFE_Py_Execute(ctx._handle, device_name, op_name,\n\u001b[0m\u001b[0;32m     53\u001b[0m                                         inputs, attrs, num_outputs)\n\u001b[0;32m     54\u001b[0m   \u001b[1;32mexcept\u001b[0m \u001b[0mcore\u001b[0m\u001b[1;33m.\u001b[0m\u001b[0m_NotOkStatusException\u001b[0m \u001b[1;32mas\u001b[0m \u001b[0me\u001b[0m\u001b[1;33m:\u001b[0m\u001b[1;33m\u001b[0m\u001b[1;33m\u001b[0m\u001b[0m\n",
      "\u001b[1;31mInvalidArgumentError\u001b[0m: Graph execution error:\n\nDetected at node 'categorical_crossentropy/softmax_cross_entropy_with_logits' defined at (most recent call last):\n    File \"C:\\Users\\smiry\\Anaconda3\\lib\\runpy.py\", line 197, in _run_module_as_main\n      return _run_code(code, main_globals, None,\n    File \"C:\\Users\\smiry\\Anaconda3\\lib\\runpy.py\", line 87, in _run_code\n      exec(code, run_globals)\n    File \"C:\\Users\\smiry\\Anaconda3\\lib\\site-packages\\ipykernel_launcher.py\", line 17, in <module>\n      app.launch_new_instance()\n    File \"C:\\Users\\smiry\\Anaconda3\\lib\\site-packages\\traitlets\\config\\application.py\", line 846, in launch_instance\n      app.start()\n    File \"C:\\Users\\smiry\\Anaconda3\\lib\\site-packages\\ipykernel\\kernelapp.py\", line 712, in start\n      self.io_loop.start()\n    File \"C:\\Users\\smiry\\Anaconda3\\lib\\site-packages\\tornado\\platform\\asyncio.py\", line 199, in start\n      self.asyncio_loop.run_forever()\n    File \"C:\\Users\\smiry\\Anaconda3\\lib\\asyncio\\base_events.py\", line 601, in run_forever\n      self._run_once()\n    File \"C:\\Users\\smiry\\Anaconda3\\lib\\asyncio\\base_events.py\", line 1905, in _run_once\n      handle._run()\n    File \"C:\\Users\\smiry\\Anaconda3\\lib\\asyncio\\events.py\", line 80, in _run\n      self._context.run(self._callback, *self._args)\n    File \"C:\\Users\\smiry\\Anaconda3\\lib\\site-packages\\ipykernel\\kernelbase.py\", line 510, in dispatch_queue\n      await self.process_one()\n    File \"C:\\Users\\smiry\\Anaconda3\\lib\\site-packages\\ipykernel\\kernelbase.py\", line 499, in process_one\n      await dispatch(*args)\n    File \"C:\\Users\\smiry\\Anaconda3\\lib\\site-packages\\ipykernel\\kernelbase.py\", line 406, in dispatch_shell\n      await result\n    File \"C:\\Users\\smiry\\Anaconda3\\lib\\site-packages\\ipykernel\\kernelbase.py\", line 730, in execute_request\n      reply_content = await reply_content\n    File \"C:\\Users\\smiry\\Anaconda3\\lib\\site-packages\\ipykernel\\ipkernel.py\", line 390, in do_execute\n      res = shell.run_cell(code, store_history=store_history, silent=silent)\n    File \"C:\\Users\\smiry\\Anaconda3\\lib\\site-packages\\ipykernel\\zmqshell.py\", line 528, in run_cell\n      return super().run_cell(*args, **kwargs)\n    File \"C:\\Users\\smiry\\Anaconda3\\lib\\site-packages\\IPython\\core\\interactiveshell.py\", line 2914, in run_cell\n      result = self._run_cell(\n    File \"C:\\Users\\smiry\\Anaconda3\\lib\\site-packages\\IPython\\core\\interactiveshell.py\", line 2960, in _run_cell\n      return runner(coro)\n    File \"C:\\Users\\smiry\\Anaconda3\\lib\\site-packages\\IPython\\core\\async_helpers.py\", line 78, in _pseudo_sync_runner\n      coro.send(None)\n    File \"C:\\Users\\smiry\\Anaconda3\\lib\\site-packages\\IPython\\core\\interactiveshell.py\", line 3185, in run_cell_async\n      has_raised = await self.run_ast_nodes(code_ast.body, cell_name,\n    File \"C:\\Users\\smiry\\Anaconda3\\lib\\site-packages\\IPython\\core\\interactiveshell.py\", line 3377, in run_ast_nodes\n      if (await self.run_code(code, result,  async_=asy)):\n    File \"C:\\Users\\smiry\\Anaconda3\\lib\\site-packages\\IPython\\core\\interactiveshell.py\", line 3457, in run_code\n      exec(code_obj, self.user_global_ns, self.user_ns)\n    File \"C:\\Users\\smiry\\AppData\\Local\\Temp\\ipykernel_5000\\233132255.py\", line 1, in <module>\n      cnn = Model.fit_generator(generator = training_set,\n    File \"C:\\Users\\smiry\\Anaconda3\\lib\\site-packages\\keras\\engine\\training.py\", line 2604, in fit_generator\n      return self.fit(\n    File \"C:\\Users\\smiry\\Anaconda3\\lib\\site-packages\\keras\\utils\\traceback_utils.py\", line 65, in error_handler\n      return fn(*args, **kwargs)\n    File \"C:\\Users\\smiry\\Anaconda3\\lib\\site-packages\\keras\\engine\\training.py\", line 1650, in fit\n      tmp_logs = self.train_function(iterator)\n    File \"C:\\Users\\smiry\\Anaconda3\\lib\\site-packages\\keras\\engine\\training.py\", line 1249, in train_function\n      return step_function(self, iterator)\n    File \"C:\\Users\\smiry\\Anaconda3\\lib\\site-packages\\keras\\engine\\training.py\", line 1233, in step_function\n      outputs = model.distribute_strategy.run(run_step, args=(data,))\n    File \"C:\\Users\\smiry\\Anaconda3\\lib\\site-packages\\keras\\engine\\training.py\", line 1222, in run_step\n      outputs = model.train_step(data)\n    File \"C:\\Users\\smiry\\Anaconda3\\lib\\site-packages\\keras\\engine\\training.py\", line 1024, in train_step\n      loss = self.compute_loss(x, y, y_pred, sample_weight)\n    File \"C:\\Users\\smiry\\Anaconda3\\lib\\site-packages\\keras\\engine\\training.py\", line 1082, in compute_loss\n      return self.compiled_loss(\n    File \"C:\\Users\\smiry\\Anaconda3\\lib\\site-packages\\keras\\engine\\compile_utils.py\", line 265, in __call__\n      loss_value = loss_obj(y_t, y_p, sample_weight=sw)\n    File \"C:\\Users\\smiry\\Anaconda3\\lib\\site-packages\\keras\\losses.py\", line 152, in __call__\n      losses = call_fn(y_true, y_pred)\n    File \"C:\\Users\\smiry\\Anaconda3\\lib\\site-packages\\keras\\losses.py\", line 284, in call\n      return ag_fn(y_true, y_pred, **self._fn_kwargs)\n    File \"C:\\Users\\smiry\\Anaconda3\\lib\\site-packages\\keras\\losses.py\", line 2004, in categorical_crossentropy\n      return backend.categorical_crossentropy(\n    File \"C:\\Users\\smiry\\Anaconda3\\lib\\site-packages\\keras\\backend.py\", line 5538, in categorical_crossentropy\n      return tf.nn.softmax_cross_entropy_with_logits(\nNode: 'categorical_crossentropy/softmax_cross_entropy_with_logits'\nlogits and labels must be broadcastable: logits_size=[32,131] labels_size=[32,24]\n\t [[{{node categorical_crossentropy/softmax_cross_entropy_with_logits}}]] [Op:__inference_train_function_1307]"
     ]
    }
   ],
   "source": [
    "cnn = Model.fit_generator(generator = training_set,\n",
    "                         steps_per_epoch = 1000,\n",
    "                         epochs = 30,\n",
    "                         validation_data = test_set,\n",
    "                         validation_steps = 100)"
   ]
  },
  {
   "cell_type": "code",
   "execution_count": 10,
   "id": "3fbe6718",
   "metadata": {},
   "outputs": [
    {
     "ename": "NameError",
     "evalue": "name 'cnn' is not defined",
     "output_type": "error",
     "traceback": [
      "\u001b[1;31m---------------------------------------------------------------------------\u001b[0m",
      "\u001b[1;31mNameError\u001b[0m                                 Traceback (most recent call last)",
      "\u001b[1;32m~\\AppData\\Local\\Temp\\ipykernel_5000\\3640948186.py\u001b[0m in \u001b[0;36m<module>\u001b[1;34m\u001b[0m\n\u001b[1;32m----> 1\u001b[1;33m \u001b[0mcnn\u001b[0m\u001b[1;33m.\u001b[0m\u001b[0mhistory\u001b[0m\u001b[1;33m\u001b[0m\u001b[1;33m\u001b[0m\u001b[0m\n\u001b[0m",
      "\u001b[1;31mNameError\u001b[0m: name 'cnn' is not defined"
     ]
    }
   ],
   "source": [
    "cnn.history"
   ]
  },
  {
   "cell_type": "code",
   "execution_count": 11,
   "id": "0ba9d47f",
   "metadata": {},
   "outputs": [],
   "source": [
    "test_labels = test_set.labels"
   ]
  },
  {
   "cell_type": "code",
   "execution_count": 12,
   "id": "90583830",
   "metadata": {},
   "outputs": [
    {
     "ename": "NameError",
     "evalue": "name 'classifier' is not defined",
     "output_type": "error",
     "traceback": [
      "\u001b[1;31m---------------------------------------------------------------------------\u001b[0m",
      "\u001b[1;31mNameError\u001b[0m                                 Traceback (most recent call last)",
      "\u001b[1;32m~\\AppData\\Local\\Temp\\ipykernel_5000\\1686262457.py\u001b[0m in \u001b[0;36m<module>\u001b[1;34m\u001b[0m\n\u001b[1;32m----> 1\u001b[1;33m \u001b[0mpredictions\u001b[0m \u001b[1;33m=\u001b[0m \u001b[0mclassifier\u001b[0m\u001b[1;33m.\u001b[0m\u001b[0mpredict\u001b[0m\u001b[1;33m(\u001b[0m\u001b[0mtest_set\u001b[0m\u001b[1;33m)\u001b[0m\u001b[1;33m\u001b[0m\u001b[1;33m\u001b[0m\u001b[0m\n\u001b[0m",
      "\u001b[1;31mNameError\u001b[0m: name 'classifier' is not defined"
     ]
    }
   ],
   "source": [
    "predictions = classifier.predict(test_set)"
   ]
  },
  {
   "cell_type": "code",
   "execution_count": null,
   "id": "435ede66",
   "metadata": {},
   "outputs": [],
   "source": []
  }
 ],
 "metadata": {
  "kernelspec": {
   "display_name": "Python 3 (ipykernel)",
   "language": "python",
   "name": "python3"
  },
  "language_info": {
   "codemirror_mode": {
    "name": "ipython",
    "version": 3
   },
   "file_extension": ".py",
   "mimetype": "text/x-python",
   "name": "python",
   "nbconvert_exporter": "python",
   "pygments_lexer": "ipython3",
   "version": "3.9.13"
  }
 },
 "nbformat": 4,
 "nbformat_minor": 5
}
